Workbook
Name Slicer_Age: #N/A
Name Slicer_Age_Group: #N/A
Name Slicer_Assisted?: #N/A
Name Slicer_Comp: #N/A
Name Slicer_Comp1: #N/A
Name Slicer_MP: #N/A
Name Slicer_Nation: #N/A
Name Slicer_Nation1: #N/A
Name Slicer_Player: #N/A
Name Slicer_Player1: #N/A
Name Slicer_players_data_postition.Pos: #N/A
Name Slicer_players_data_postition.Pos1: #N/A
Name Slicer_Pos: #N/A
Name Slicer_Scored?: #N/A

Sheet Data_Hub
A1: Row Labels | B1: Goals+Assists | C1: Matches Played
A2: Harry Kane | B2: 41 | C2: 31
A3: Erling Haaland | B3: 35 | C3: 35
A4: Michael Olise | B4: 34 | C4: 32
A5: Bruno Fernandes | B5: 30 | C5: 35
A6: Kylian Mbappé | B6: 30 | C6: 31
A7: Luis Díaz | B7: 29 | C7: 32
A8: Lamine Yamal | B8: 27 | C8: 28
A9: Deniz Undav | B9: 26 | C9: 29
A10: Vedat Muriqi | B10: 24 | C10: 37
A11: Federico Dimarco | B11: 23 | C11: 35
A19: Row Labels | B19: Count of Player | C19: Country | D19: Count of player
A20: Albania | B20: 10 | C20: Albania | D20: =_xlfn.XLOOKUP(C20,$A$20:$A$132,$B$20:$B$132,0) -> 10
A21: Algeria | B21: 22 | C21: Algeria | D21: =_xlfn.XLOOKUP(C21,$A$20:$A$132,$B$20:$B$132,0) -> 22
A22: Angola | B22: 7 | C22: Angola | D22: =_xlfn.XLOOKUP(C22,$A$20:$A$132,$B$20:$B$132,0) -> 7
A23: Argentina | B23: 66 | C23: Argentina | D23: =_xlfn.XLOOKUP(C23,$A$20:$A$132,$B$20:$B$132,0) -> 66
A24: Armenia | B24: 2 | C24: Armenia | D24: =_xlfn.XLOOKUP(C24,$A$20:$A$132,$B$20:$B$132,0) -> 2
A25: Australia | B25: 3 | C25: Australia | D25: =_xlfn.XLOOKUP(C25,$A$20:$A$132,$B$20:$B$132,0) -> 3
A26: Austria | B26: 29 | C26: Austria | D26: =_xlfn.XLOOKUP(C26,$A$20:$A$132,$B$20:$B$132,0) -> 29
A27: Barbados | B27: 1 | C27: Barbados | D27: =_xlfn.XLOOKUP(C27,$A$20:$A$132,$B$20:$B$132,0) -> 1
A28: Belgium | B28: 49 | C28: Belgium | D28: =_xlfn.XLOOKUP(C28,$A$20:$A$132,$B$20:$B$132,0) -> 49
A29: Benin | B29: 2 | C29: Benin | D29: =_xlfn.XLOOKUP(C29,$A$20:$A$132,$B$20:$B$132,0) -> 2
A30: Bosnia and Herzegovina | B30: 9 | C30: Bosnia and Herzegovina | D30: =_xlfn.XLOOKUP(C30,$A$20:$A$132,$B$20:$B$132,0) -> 9
A31: Brazil | B31: 81 | C31: Brazil | D31: =_xlfn.XLOOKUP(C31,$A$20:$A$132,$B$20:$B$132,0) -> 81
... A132: Zimbabwe | B132: 3 | C132: Zimbabwe | D132: =_xlfn.XLOOKUP(C132,$A$20:$A$132,$B$20:$B$132,0) -> 3
A134: Row Labels | B134: Average_Goal_Con | C134: Sum of Gls | D134: Sum of MP
A135: Harry Kane | B135: 1.3225806 | C135: 36 | D135: 31
A136: Erling Haaland | B136: 1 | C136: 27 | D136: 35
A137: Kylian Mbappé | B137: 0.96774194 | C137: 25 | D137: 31
A138: Vedat Muriqi | B138: 0.64864865 | C138: 23 | D138: 37
A139: Igor Thiago | B139: 0.60526316 | C139: 22 | D139: 38
A140: Deniz Undav | B140: 0.89655172 | C140: 19 | D140: 29
A141: Serhou Guirassy | B141: 0.54545455 | C141: 17 | D141: 33
A142: Ante Budimir | B142: 0.45945946 | C142: 17 | D142: 37
A143: Lautaro Martínez | B143: 0.76666667 | C143: 17 | D143: 30
A144: Ferrán Torres | B144: 0.54545455 | C144: 16 | D144: 33
A145: Grand Total | B145: 0.77578213 | C145: 219 | D145: 334
A152: Row Labels | B152: Count of Player | C152: Goals count per postition
A153: DF | B153: 930 | C153: 666
A154: FW | B154: 705 | C154: 2490
...

Sheet Overview
K1: ⚽ EUROPEAN FOOTBALL PLAYER ANALYTICS 2025/26
K4: =GETPIVOTDATA("[Measures].[Count player]",Data_Hub!$A$187) -> 2490 | M4: =GETPIVOTDATA("[Measures].[Club_Count]",Data_Hub!$A$204) -> 96 | O4: =GETPIVOTDATA("[Measures].[Country_Count]",Data_Hub!$A$203) -> 113 | Q4: =GETPIVOTDATA("[Measures].[Goals_count]",Data_Hub!$A$203) -> 4534 | S4: =GETPIVOTDATA("[Measures].[Assists_Count]",Data_Hub!$A$203) -> 3182
F11: =K4 -> 2490

Sheet Overview-Main
I10: =GETPIVOTDATA("[Measures].[Count player]",Data_Hub!$A$187) -> 2490

Sheet Players_Data
